2016-08-19 12:54:42.0238 ERROR System.AggregateException: One or more errors occurred. ---> Parse.ParseException: Object not found.
   at Parse.Internal.ParseCommandRunner.<>c__DisplayClass2.<RunCommandAsync>b__1(Task`1 t)
   at Parse.Internal.InternalExtensions.<>c__DisplayClass7`1.<OnSuccess>b__6(Task t)
   at System.Threading.Tasks.ContinuationResultTaskFromTask`1.InnerInvoke()
   at System.Threading.Tasks.Task.Execute()
--- End of stack trace from previous location where exception was thrown ---
   at Parse.Internal.InternalExtensions.<>c__DisplayClass7`1.<OnSuccess>b__6(Task t)
   at System.Threading.Tasks.ContinuationResultTaskFromTask`1.InnerInvoke()
   at System.Threading.Tasks.Task.Execute()
--- End of stack trace from previous location where exception was thrown ---
   at Parse.Internal.InternalExtensions.<>c__DisplayClass7`1.<OnSuccess>b__6(Task t)
   at System.Threading.Tasks.ContinuationResultTaskFromTask`1.InnerInvoke()
   at System.Threading.Tasks.Task.Execute()
--- End of stack trace from previous location where exception was thrown ---
   at Parse.Internal.InternalExtensions.<>c__DisplayClass7`1.<OnSuccess>b__6(Task t)
   at System.Threading.Tasks.ContinuationResultTaskFromTask`1.InnerInvoke()
   at System.Threading.Tasks.Task.Execute()
--- End of stack trace from previous location where exception was thrown ---
   at Parse.Internal.InternalExtensions.<>c__DisplayClass7`1.<OnSuccess>b__6(Task t)
   at System.Threading.Tasks.ContinuationResultTaskFromTask`1.InnerInvoke()
   at System.Threading.Tasks.Task.Execute()
   --- End of inner exception stack trace ---
   at System.Threading.Tasks.Task`1.GetResultCore(Boolean waitCompletionNotification)
   at MyMentor.BL.Extentions.ParseObjectExtentions.GetPointerObject[T](ParseObject parseObject, String fieldName) in d:\Tfs_Workspace\MyMentor\MyMentor.BL\Extentions\ParseObjectExtentions.cs:line 220
   at MyMentor.Controllers.AccountController.Update(String regAsTeacher) in d:\Tfs_Workspace\MyMentor\MyMentor\Controllers\AccountController.cs:line 406
   at lambda_method(Closure , ControllerBase , Object[] )
   at System.Web.Mvc.ReflectedActionDescriptor.Execute(ControllerContext controllerContext, IDictionary`2 parameters)
   at System.Web.Mvc.ControllerActionInvoker.InvokeActionMethod(ControllerContext controllerContext, ActionDescriptor actionDescriptor, IDictionary`2 parameters)
   at System.Web.Mvc.Async.AsyncControllerActionInvoker.<BeginInvokeSynchronousActionMethod>b__36(IAsyncResult asyncResult, ActionInvocation innerInvokeState)
   at System.Web.Mvc.Async.AsyncResultWrapper.WrappedAsyncResult`2.CallEndDelegate(IAsyncResult asyncResult)
   at System.Web.Mvc.Async.AsyncControllerActionInvoker.EndInvokeActionMethod(IAsyncResult asyncResult)
   at System.Web.Mvc.Async.AsyncControllerActionInvoker.AsyncInvocationWithFilters.<InvokeActionMethodFilterAsynchronouslyRecursive>b__3c()
   at System.Web.Mvc.Async.AsyncControllerActionInvoker.AsyncInvocationWithFilters.<>c__DisplayClass45.<InvokeActionMethodFilterAsynchronouslyRecursive>b__3e()
   at System.Web.Mvc.Async.AsyncControllerActionInvoker.EndInvokeActionMethodWithFilters(IAsyncResult asyncResult)
   at System.Web.Mvc.Async.AsyncControllerActionInvoker.<>c__DisplayClass1e.<>c__DisplayClass28.<BeginInvokeAction>b__19()
   at System.Web.Mvc.Async.AsyncControllerActionInvoker.<>c__DisplayClass1e.<BeginInvokeAction>b__1b(IAsyncResult asyncResult)
   at System.Web.Mvc.Async.AsyncControllerActionInvoker.EndInvokeAction(IAsyncResult asyncResult)
   at System.Web.Mvc.Controller.<BeginExecuteCore>b__1d(IAsyncResult asyncResult, ExecuteCoreState innerState)
   at System.Web.Mvc.Async.AsyncResultWrapper.WrappedAsyncVoid`1.CallEndDelegate(IAsyncResult asyncResult)
   at System.Web.Mvc.Controller.EndExecuteCore(IAsyncResult asyncResult)
   at System.Web.Mvc.Async.AsyncResultWrapper.WrappedAsyncVoid`1.CallEndDelegate(IAsyncResult asyncResult)
   at System.Web.Mvc.Controller.EndExecute(IAsyncResult asyncResult)
   at System.Web.Mvc.MvcHandler.<BeginProcessRequest>b__4(IAsyncResult asyncResult, ProcessRequestState innerState)
   at System.Web.Mvc.Async.AsyncResultWrapper.WrappedAsyncVoid`1.CallEndDelegate(IAsyncResult asyncResult)
   at System.Web.Mvc.MvcHandler.EndProcessRequest(IAsyncResult asyncResult)
   at System.Web.HttpApplication.CallHandlerExecutionStep.System.Web.HttpApplication.IExecutionStep.Execute()
   at System.Web.HttpApplication.ExecuteStep(IExecutionStep step, Boolean& completedSynchronously)
---> (Inner Exception #0) Parse.ParseException: Object not found.
   at Parse.Internal.ParseCommandRunner.<>c__DisplayClass2.<RunCommandAsync>b__1(Task`1 t)
   at Parse.Internal.InternalExtensions.<>c__DisplayClass7`1.<OnSuccess>b__6(Task t)
   at System.Threading.Tasks.ContinuationResultTaskFromTask`1.InnerInvoke()
   at System.Threading.Tasks.Task.Execute()
--- End of stack trace from previous location where exception was thrown ---
   at Parse.Internal.InternalExtensions.<>c__DisplayClass7`1.<OnSuccess>b__6(Task t)
   at System.Threading.Tasks.ContinuationResultTaskFromTask`1.InnerInvoke()
   at System.Threading.Tasks.Task.Execute()
--- End of stack trace from previous location where exception was thrown ---
   at Parse.Internal.InternalExtensions.<>c__DisplayClass7`1.<OnSuccess>b__6(Task t)
   at System.Threading.Tasks.ContinuationResultTaskFromTask`1.InnerInvoke()
   at System.Threading.Tasks.Task.Execute()
--- End of stack trace from previous location where exception was thrown ---
   at Parse.Internal.InternalExtensions.<>c__DisplayClass7`1.<OnSuccess>b__6(Task t)
   at System.Threading.Tasks.ContinuationResultTaskFromTask`1.InnerInvoke()
   at System.Threading.Tasks.Task.Execute()
--- End of stack trace from previous location where exception was thrown ---
   at Parse.Internal.InternalExtensions.<>c__DisplayClass7`1.<OnSuccess>b__6(Task t)
   at System.Threading.Tasks.ContinuationResultTaskFromTask`1.InnerInvoke()
   at System.Threading.Tasks.Task.Execute()<---

2016-08-19 12:56:31.1455 ERROR System.AggregateException: One or more errors occurred. ---> Parse.ParseException: Object not found.
   at Parse.Internal.ParseCommandRunner.<>c__DisplayClass2.<RunCommandAsync>b__1(Task`1 t)
   at Parse.Internal.InternalExtensions.<>c__DisplayClass7`1.<OnSuccess>b__6(Task t)
   at System.Threading.Tasks.ContinuationResultTaskFromTask`1.InnerInvoke()
   at System.Threading.Tasks.Task.Execute()
--- End of stack trace from previous location where exception was thrown ---
   at Parse.Internal.InternalExtensions.<>c__DisplayClass7`1.<OnSuccess>b__6(Task t)
   at System.Threading.Tasks.ContinuationResultTaskFromTask`1.InnerInvoke()
   at System.Threading.Tasks.Task.Execute()
--- End of stack trace from previous location where exception was thrown ---
   at Parse.Internal.InternalExtensions.<>c__DisplayClass7`1.<OnSuccess>b__6(Task t)
   at System.Threading.Tasks.ContinuationResultTaskFromTask`1.InnerInvoke()
   at System.Threading.Tasks.Task.Execute()
--- End of stack trace from previous location where exception was thrown ---
   at Parse.Internal.InternalExtensions.<>c__DisplayClass7`1.<OnSuccess>b__6(Task t)
   at System.Threading.Tasks.ContinuationResultTaskFromTask`1.InnerInvoke()
   at System.Threading.Tasks.Task.Execute()
--- End of stack trace from previous location where exception was thrown ---
   at Parse.Internal.InternalExtensions.<>c__DisplayClass7`1.<OnSuccess>b__6(Task t)
   at System.Threading.Tasks.ContinuationResultTaskFromTask`1.InnerInvoke()
   at System.Threading.Tasks.Task.Execute()
   --- End of inner exception stack trace ---
   at System.Threading.Tasks.Task`1.GetResultCore(Boolean waitCompletionNotification)
   at MyMentor.BL.Extentions.ParseObjectExtentions.GetPointerObject[T](ParseObject parseObject, String fieldName) in d:\Tfs_Workspace\MyMentor\MyMentor.BL\Extentions\ParseObjectExtentions.cs:line 220
   at MyMentor.Controllers.AccountController.Update(String regAsTeacher) in d:\Tfs_Workspace\MyMentor\MyMentor\Controllers\AccountController.cs:line 406
   at lambda_method(Closure , ControllerBase , Object[] )
   at System.Web.Mvc.ReflectedActionDescriptor.Execute(ControllerContext controllerContext, IDictionary`2 parameters)
   at System.Web.Mvc.ControllerActionInvoker.InvokeActionMethod(ControllerContext controllerContext, ActionDescriptor actionDescriptor, IDictionary`2 parameters)
   at System.Web.Mvc.Async.AsyncControllerActionInvoker.<BeginInvokeSynchronousActionMethod>b__36(IAsyncResult asyncResult, ActionInvocation innerInvokeState)
   at System.Web.Mvc.Async.AsyncResultWrapper.WrappedAsyncResult`2.CallEndDelegate(IAsyncResult asyncResult)
   at System.Web.Mvc.Async.AsyncControllerActionInvoker.EndInvokeActionMethod(IAsyncResult asyncResult)
   at System.Web.Mvc.Async.AsyncControllerActionInvoker.AsyncInvocationWithFilters.<InvokeActionMethodFilterAsynchronouslyRecursive>b__3c()
   at System.Web.Mvc.Async.AsyncControllerActionInvoker.AsyncInvocationWithFilters.<>c__DisplayClass45.<InvokeActionMethodFilterAsynchronouslyRecursive>b__3e()
   at System.Web.Mvc.Async.AsyncControllerActionInvoker.EndInvokeActionMethodWithFilters(IAsyncResult asyncResult)
   at System.Web.Mvc.Async.AsyncControllerActionInvoker.<>c__DisplayClass1e.<>c__DisplayClass28.<BeginInvokeAction>b__19()
   at System.Web.Mvc.Async.AsyncControllerActionInvoker.<>c__DisplayClass1e.<BeginInvokeAction>b__1b(IAsyncResult asyncResult)
   at System.Web.Mvc.Async.AsyncControllerActionInvoker.EndInvokeAction(IAsyncResult asyncResult)
   at System.Web.Mvc.Controller.<BeginExecuteCore>b__1d(IAsyncResult asyncResult, ExecuteCoreState innerState)
   at System.Web.Mvc.Async.AsyncResultWrapper.WrappedAsyncVoid`1.CallEndDelegate(IAsyncResult asyncResult)
   at System.Web.Mvc.Controller.EndExecuteCore(IAsyncResult asyncResult)
   at System.Web.Mvc.Async.AsyncResultWrapper.WrappedAsyncVoid`1.CallEndDelegate(IAsyncResult asyncResult)
   at System.Web.Mvc.Controller.EndExecute(IAsyncResult asyncResult)
   at System.Web.Mvc.MvcHandler.<BeginProcessRequest>b__4(IAsyncResult asyncResult, ProcessRequestState innerState)
   at System.Web.Mvc.Async.AsyncResultWrapper.WrappedAsyncVoid`1.CallEndDelegate(IAsyncResult asyncResult)
   at System.Web.Mvc.MvcHandler.EndProcessRequest(IAsyncResult asyncResult)
   at System.Web.HttpApplication.CallHandlerExecutionStep.System.Web.HttpApplication.IExecutionStep.Execute()
   at System.Web.HttpApplication.ExecuteStep(IExecutionStep step, Boolean& completedSynchronously)
---> (Inner Exception #0) Parse.ParseException: Object not found.
   at Parse.Internal.ParseCommandRunner.<>c__DisplayClass2.<RunCommandAsync>b__1(Task`1 t)
   at Parse.Internal.InternalExtensions.<>c__DisplayClass7`1.<OnSuccess>b__6(Task t)
   at System.Threading.Tasks.ContinuationResultTaskFromTask`1.InnerInvoke()
   at System.Threading.Tasks.Task.Execute()
--- End of stack trace from previous location where exception was thrown ---
   at Parse.Internal.InternalExtensions.<>c__DisplayClass7`1.<OnSuccess>b__6(Task t)
   at System.Threading.Tasks.ContinuationResultTaskFromTask`1.InnerInvoke()
   at System.Threading.Tasks.Task.Execute()
--- End of stack trace from previous location where exception was thrown ---
   at Parse.Internal.InternalExtensions.<>c__DisplayClass7`1.<OnSuccess>b__6(Task t)
   at System.Threading.Tasks.ContinuationResultTaskFromTask`1.InnerInvoke()
   at System.Threading.Tasks.Task.Execute()
--- End of stack trace from previous location where exception was thrown ---
   at Parse.Internal.InternalExtensions.<>c__DisplayClass7`1.<OnSuccess>b__6(Task t)
   at System.Threading.Tasks.ContinuationResultTaskFromTask`1.InnerInvoke()
   at System.Threading.Tasks.Task.Execute()
--- End of stack trace from previous location where exception was thrown ---
   at Parse.Internal.InternalExtensions.<>c__DisplayClass7`1.<OnSuccess>b__6(Task t)
   at System.Threading.Tasks.ContinuationResultTaskFromTask`1.InnerInvoke()
   at System.Threading.Tasks.Task.Execute()<---

2016-08-19 12:59:23.6513 ERROR System.AggregateException: One or more errors occurred. ---> Parse.ParseException: Object not found.
   at Parse.Internal.ParseCommandRunner.<>c__DisplayClass2.<RunCommandAsync>b__1(Task`1 t)
   at Parse.Internal.InternalExtensions.<>c__DisplayClass7`1.<OnSuccess>b__6(Task t)
   at System.Threading.Tasks.ContinuationResultTaskFromTask`1.InnerInvoke()
   at System.Threading.Tasks.Task.Execute()
--- End of stack trace from previous location where exception was thrown ---
   at Parse.Internal.InternalExtensions.<>c__DisplayClass7`1.<OnSuccess>b__6(Task t)
   at System.Threading.Tasks.ContinuationResultTaskFromTask`1.InnerInvoke()
   at System.Threading.Tasks.Task.Execute()
--- End of stack trace from previous location where exception was thrown ---
   at Parse.Internal.InternalExtensions.<>c__DisplayClass7`1.<OnSuccess>b__6(Task t)
   at System.Threading.Tasks.ContinuationResultTaskFromTask`1.InnerInvoke()
   at System.Threading.Tasks.Task.Execute()
--- End of stack trace from previous location where exception was thrown ---
   at Parse.Internal.InternalExtensions.<>c__DisplayClass7`1.<OnSuccess>b__6(Task t)
   at System.Threading.Tasks.ContinuationResultTaskFromTask`1.InnerInvoke()
   at System.Threading.Tasks.Task.Execute()
--- End of stack trace from previous location where exception was thrown ---
   at Parse.Internal.InternalExtensions.<>c__DisplayClass7`1.<OnSuccess>b__6(Task t)
   at System.Threading.Tasks.ContinuationResultTaskFromTask`1.InnerInvoke()
   at System.Threading.Tasks.Task.Execute()
   --- End of inner exception stack trace ---
   at System.Threading.Tasks.Task`1.GetResultCore(Boolean waitCompletionNotification)
   at MyMentor.BL.Extentions.ParseObjectExtentions.GetPointerObject[T](ParseObject parseObject, String fieldName) in d:\Tfs_Workspace\MyMentor\MyMentor.BL\Extentions\ParseObjectExtentions.cs:line 222
---> (Inner Exception #0) Parse.ParseException: Object not found.
   at Parse.Internal.ParseCommandRunner.<>c__DisplayClass2.<RunCommandAsync>b__1(Task`1 t)
   at Parse.Internal.InternalExtensions.<>c__DisplayClass7`1.<OnSuccess>b__6(Task t)
   at System.Threading.Tasks.ContinuationResultTaskFromTask`1.InnerInvoke()
   at System.Threading.Tasks.Task.Execute()
--- End of stack trace from previous location where exception was thrown ---
   at Parse.Internal.InternalExtensions.<>c__DisplayClass7`1.<OnSuccess>b__6(Task t)
   at System.Threading.Tasks.ContinuationResultTaskFromTask`1.InnerInvoke()
   at System.Threading.Tasks.Task.Execute()
--- End of stack trace from previous location where exception was thrown ---
   at Parse.Internal.InternalExtensions.<>c__DisplayClass7`1.<OnSuccess>b__6(Task t)
   at System.Threading.Tasks.ContinuationResultTaskFromTask`1.InnerInvoke()
   at System.Threading.Tasks.Task.Execute()
--- End of stack trace from previous location where exception was thrown ---
   at Parse.Internal.InternalExtensions.<>c__DisplayClass7`1.<OnSuccess>b__6(Task t)
   at System.Threading.Tasks.ContinuationResultTaskFromTask`1.InnerInvoke()
   at System.Threading.Tasks.Task.Execute()
--- End of stack trace from previous location where exception was thrown ---
   at Parse.Internal.InternalExtensions.<>c__DisplayClass7`1.<OnSuccess>b__6(Task t)
   at System.Threading.Tasks.ContinuationResultTaskFromTask`1.InnerInvoke()
   at System.Threading.Tasks.Task.Execute()<---

2016-08-19 12:59:33.9540 ERROR System.AggregateException: One or more errors occurred. ---> Parse.ParseException: Object not found.
   at Parse.Internal.ParseCommandRunner.<>c__DisplayClass2.<RunCommandAsync>b__1(Task`1 t)
   at Parse.Internal.InternalExtensions.<>c__DisplayClass7`1.<OnSuccess>b__6(Task t)
   at System.Threading.Tasks.ContinuationResultTaskFromTask`1.InnerInvoke()
   at System.Threading.Tasks.Task.Execute()
--- End of stack trace from previous location where exception was thrown ---
   at Parse.Internal.InternalExtensions.<>c__DisplayClass7`1.<OnSuccess>b__6(Task t)
   at System.Threading.Tasks.ContinuationResultTaskFromTask`1.InnerInvoke()
   at System.Threading.Tasks.Task.Execute()
--- End of stack trace from previous location where exception was thrown ---
   at Parse.Internal.InternalExtensions.<>c__DisplayClass7`1.<OnSuccess>b__6(Task t)
   at System.Threading.Tasks.ContinuationResultTaskFromTask`1.InnerInvoke()
   at System.Threading.Tasks.Task.Execute()
--- End of stack trace from previous location where exception was thrown ---
   at Parse.Internal.InternalExtensions.<>c__DisplayClass7`1.<OnSuccess>b__6(Task t)
   at System.Threading.Tasks.ContinuationResultTaskFromTask`1.InnerInvoke()
   at System.Threading.Tasks.Task.Execute()
--- End of stack trace from previous location where exception was thrown ---
   at Parse.Internal.InternalExtensions.<>c__DisplayClass7`1.<OnSuccess>b__6(Task t)
   at System.Threading.Tasks.ContinuationResultTaskFromTask`1.InnerInvoke()
   at System.Threading.Tasks.Task.Execute()
   --- End of inner exception stack trace ---
   at System.Threading.Tasks.Task`1.GetResultCore(Boolean waitCompletionNotification)
   at MyMentor.BL.Extentions.ParseObjectExtentions.GetPointerObject[T](ParseObject parseObject, String fieldName) in d:\Tfs_Workspace\MyMentor\MyMentor.BL\Extentions\ParseObjectExtentions.cs:line 222
---> (Inner Exception #0) Parse.ParseException: Object not found.
   at Parse.Internal.ParseCommandRunner.<>c__DisplayClass2.<RunCommandAsync>b__1(Task`1 t)
   at Parse.Internal.InternalExtensions.<>c__DisplayClass7`1.<OnSuccess>b__6(Task t)
   at System.Threading.Tasks.ContinuationResultTaskFromTask`1.InnerInvoke()
   at System.Threading.Tasks.Task.Execute()
--- End of stack trace from previous location where exception was thrown ---
   at Parse.Internal.InternalExtensions.<>c__DisplayClass7`1.<OnSuccess>b__6(Task t)
   at System.Threading.Tasks.ContinuationResultTaskFromTask`1.InnerInvoke()
   at System.Threading.Tasks.Task.Execute()
--- End of stack trace from previous location where exception was thrown ---
   at Parse.Internal.InternalExtensions.<>c__DisplayClass7`1.<OnSuccess>b__6(Task t)
   at System.Threading.Tasks.ContinuationResultTaskFromTask`1.InnerInvoke()
   at System.Threading.Tasks.Task.Execute()
--- End of stack trace from previous location where exception was thrown ---
   at Parse.Internal.InternalExtensions.<>c__DisplayClass7`1.<OnSuccess>b__6(Task t)
   at System.Threading.Tasks.ContinuationResultTaskFromTask`1.InnerInvoke()
   at System.Threading.Tasks.Task.Execute()
--- End of stack trace from previous location where exception was thrown ---
   at Parse.Internal.InternalExtensions.<>c__DisplayClass7`1.<OnSuccess>b__6(Task t)
   at System.Threading.Tasks.ContinuationResultTaskFromTask`1.InnerInvoke()
   at System.Threading.Tasks.Task.Execute()<---

2016-08-19 13:26:41.5033 ERROR Parse.ParseException: Invalid username/password.
   at Parse.Internal.ParseCommandRunner.<>c__DisplayClass2.<RunCommandAsync>b__1(Task`1 t)
   at Parse.Internal.InternalExtensions.<>c__DisplayClass7`1.<OnSuccess>b__6(Task t)
   at System.Threading.Tasks.ContinuationResultTaskFromTask`1.InnerInvoke()
   at System.Threading.Tasks.Task.Execute()
--- End of stack trace from previous location where exception was thrown ---
   at Parse.Internal.InternalExtensions.<>c__DisplayClass7`1.<OnSuccess>b__6(Task t)
   at System.Threading.Tasks.ContinuationResultTaskFromTask`1.InnerInvoke()
   at System.Threading.Tasks.Task.Execute()
--- End of stack trace from previous location where exception was thrown ---
   at Parse.Internal.InternalExtensions.<>c__DisplayClass7`1.<OnSuccess>b__6(Task t)
   at System.Threading.Tasks.ContinuationResultTaskFromTask`1.InnerInvoke()
   at System.Threading.Tasks.Task.Execute()
--- End of stack trace from previous location where exception was thrown ---
   at System.Runtime.CompilerServices.TaskAwaiter.ThrowForNonSuccess(Task task)
   at System.Runtime.CompilerServices.TaskAwaiter.HandleNonSuccessAndDebuggerNotification(Task task)
   at System.Runtime.CompilerServices.TaskAwaiter`1.GetResult()
   at MyMentor.Account.MyMentorUserManager.<Login>d__32.MoveNext() in d:\Tfs_Workspace\MyMentor\MyMentor.BL\DomainServices\MyMentorUserManager.cs:line 225
--- End of stack trace from previous location where exception was thrown ---
   at System.Runtime.CompilerServices.TaskAwaiter.ThrowForNonSuccess(Task task)
   at System.Runtime.CompilerServices.TaskAwaiter.HandleNonSuccessAndDebuggerNotification(Task task)
   at System.Runtime.CompilerServices.TaskAwaiter`1.GetResult()
   at MyMentor.Controllers.AccountController.<Login>d__8.MoveNext() in d:\Tfs_Workspace\MyMentor\MyMentor\Controllers\AccountController.cs:line 95
2016-08-19 16:11:32.3521 ERROR Parse.ParseException: Invalid username/password.
   at Parse.Internal.ParseCommandRunner.<>c__DisplayClass2.<RunCommandAsync>b__1(Task`1 t)
   at Parse.Internal.InternalExtensions.<>c__DisplayClass7`1.<OnSuccess>b__6(Task t)
   at System.Threading.Tasks.ContinuationResultTaskFromTask`1.InnerInvoke()
   at System.Threading.Tasks.Task.Execute()
--- End of stack trace from previous location where exception was thrown ---
   at Parse.Internal.InternalExtensions.<>c__DisplayClass7`1.<OnSuccess>b__6(Task t)
   at System.Threading.Tasks.ContinuationResultTaskFromTask`1.InnerInvoke()
   at System.Threading.Tasks.Task.Execute()
--- End of stack trace from previous location where exception was thrown ---
   at Parse.Internal.InternalExtensions.<>c__DisplayClass7`1.<OnSuccess>b__6(Task t)
   at System.Threading.Tasks.ContinuationResultTaskFromTask`1.InnerInvoke()
   at System.Threading.Tasks.Task.Execute()
--- End of stack trace from previous location where exception was thrown ---
   at System.Runtime.CompilerServices.TaskAwaiter.ThrowForNonSuccess(Task task)
   at System.Runtime.CompilerServices.TaskAwaiter.HandleNonSuccessAndDebuggerNotification(Task task)
   at System.Runtime.CompilerServices.TaskAwaiter`1.GetResult()
   at MyMentor.Account.MyMentorUserManager.<Login>d__32.MoveNext() in d:\Tfs_Workspace\MyMentor\MyMentor.BL\DomainServices\MyMentorUserManager.cs:line 225
--- End of stack trace from previous location where exception was thrown ---
   at System.Runtime.CompilerServices.TaskAwaiter.ThrowForNonSuccess(Task task)
   at System.Runtime.CompilerServices.TaskAwaiter.HandleNonSuccessAndDebuggerNotification(Task task)
   at System.Runtime.CompilerServices.TaskAwaiter`1.GetResult()
   at MyMentor.Controllers.AccountController.<Login>d__8.MoveNext() in d:\Tfs_Workspace\MyMentor\MyMentor\Controllers\AccountController.cs:line 95
2016-08-19 16:16:43.9001 ERROR System.Exception: test 123
   at MyMentor.Controllers.CuponController.<GetSecondPageDataAfterPaymentCancelation>d__2c.MoveNext() in d:\Tfs_Workspace\MyMentor\MyMentor\Controllers\CuponController.cs:line 234
